Workbook

Sheet Historical Batch Data
A1: Historical Batch Data (24 Months) – Expanded Synthetic Dataset
A2: 600 synthetic historical batches with repeated Material/Site history, point-in-time QC backlog, and date-based rolling OOS features.
A4: Batch ID | B4: Material | C4: Supplier Number | D4: Supplier Name | E4: CMO Site | F4: Prediction / Start Date | G4: QC Backlog at Start | H4: Planned Release Date | I4: Actual Release Date | J4: Recent OOS Count - Prior 90 Days | K4: Number of OOS Events (Batch) | L4: Number of Deviations | M4: QC Sample Count | N4: Testing Type / Complexity
A5: B-4533 | B5: 110027379 | C5: 1083382 | D5: ApexNova Pharma | E5: SSEC | F5: 45580 | G5: 15 | H5: 45597 | I5: 45598 | J5: =COUNTIFS('OOS Events'!$C:$C,B5,'OOS Events'!$D:$D,C5,'OOS Events'!$E:$E,">="&D5-90,'OOS Events'!$E:$E,"<"&D5) -> 0 | K5: =COUNTIF('OOS Events'!$B:$B,A5) -> 0 | L5: 2 | M5: 9 | N5: Standard / Low
A6: B-5022 | B6: 110032050 | C6: 1077103 | D6: Evergreen BioWorks | E6: SDEB | F6: 45580 | G6: 14 | H6: 45614 | I6: 45614 | J6: =COUNTIFS('OOS Events'!$C:$C,B6,'OOS Events'!$D:$D,C6,'OOS Events'!$E:$E,">="&D6-90,'OOS Events'!$E:$E,"<"&D6) -> 0 | K6: =COUNTIF('OOS Events'!$B:$B,A6) -> 1 | L6: 0 | M6: 18 | N6: Stability / High
A7: B-4768 | B7: 110028927 | C7: 1077103 | D7: Evergreen BioWorks | E7: SKRB | F7: 45582 | G7: 11 | H7: 45600 | I7: 45600 | J7: =COUNTIFS('OOS Events'!$C:$C,B7,'OOS Events'!$D:$D,C7,'OOS Events'!$E:$E,">="&D7-90,'OOS Events'!$E:$E,"<"&D7) -> 0 | K7: =COUNTIF('OOS Events'!$B:$B,A7) -> 1 | L7: 1 | M7: 14 | N7: Standard / Low
A8: B-4631 | B8: 100011307 | C8: 1088815 | D8: ApexNova Pharma | E8: SUSB | F8: 45583 | G8: 4 | H8: 45619 | I8: 45619 | J8: =COUNTIFS('OOS Events'!$C:$C,B8,'OOS Events'!$D:$D,C8,'OOS Events'!$E:$E,">="&D8-90,'OOS Events'!$E:$E,"<"&D8) -> 0 | K8: =COUNTIF('OOS Events'!$B:$B,A8) -> 2 | L8: 0 | M8: 41 | N8: Sterility / High
A9: B-5120 | B9: 110025553 | C9: 1083989 | D9: VertexHill Biotech | E9: SDEB | F9: 45583 | G9: 18 | H9: 45604 | I9: 45605 | J9: =COUNTIFS('OOS Events'!$C:$C,B9,'OOS Events'!$D:$D,C9,'OOS Events'!$E:$E,">="&D9-90,'OOS Events'!$E:$E,"<"&D9) -> 0 | K9: =COUNTIF('OOS Events'!$B:$B,A9) -> 0 | L9: 0 | M9: 8 | N9: Standard / Medium
A10: B-4983 | B10: 110041752 | C10: 1077103 | D10: Evergreen BioWorks | E10: SCNC | F10: 45584 | G10: 21 | H10: 45613 | I10: 45614 | J10: =COUNTIFS('OOS Events'!$C:$C,B10,'OOS Events'!$D:$D,C10,'OOS Events'!$E:$E,">="&D10-90,'OOS Events'!$E:$E,"<"&D10) -> 0 | K10: =COUNTIF('OOS Events'!$B:$B,A10) -> 1 | L10: 0 | M10: 34 | N10: Identity & Purity / Medium
A11: B-4729 | B11: 110028926 | C11: 1077103 | D11: Evergreen BioWorks | E11: SUSB | F11: 45586 | G11: 7 | H11: 45613 | I11: 45615 | J11: =COUNTIFS('OOS Events'!$C:$C,B11,'OOS Events'!$D:$D,C11,'OOS Events'!$E:$E,">="&D11-90,'OOS Events'!$E:$E,"<"&D11) -> 0 | K11: =COUNTIF('OOS Events'!$B:$B,A11) -> 0 | L11: 2 | M11: 16 | N11: Extended / Medium
A12: B-4592 | B12: 110022873 | C12: 1088815 | D12: ApexNova Pharma | E12: SKRB | F12: 45587 | G12: 15 | H12: 45604 | I12: 45604 | J12: =COUNTIFS('OOS Events'!$C:$C,B12,'OOS Events'!$D:$D,C12,'OOS Events'!$E:$E,">="&D12-90,'OOS Events'!$E:$E,"<"&D12) -> 0 | K12: =COUNTIF('OOS Events'!$B:$B,A12) -> 0 | L12: 0 | M12: 12 | N12: Standard / Low
A13: B-5081 | B13: 110025554 | C13: 1083989 | D13: VertexHill Biotech | E13: SCNC | F13: 45587 | G13: 21 | H13: 45629 | I13: 45630 | J13: =COUNTIFS('OOS Events'!$C:$C,B13,'OOS Events'!$D:$D,C13,'OOS Events'!$E:$E,">="&D13-90,'OOS Events'!$E:$E,"<"&D13) -> 0 | K13: =COUNTIF('OOS Events'!$B:$B,A13) -> 0 | L13: 1 | M13: 19 | N13: Stability / High
A14: B-4944 | B14: 110041756 | C14: 1077103 | D14: Evergreen BioWorks | E14: SKRB | F14: 45588 | G14: 13 | H14: 45607 | I14: 45606 | J14: =COUNTIFS('OOS Events'!$C:$C,B14,'OOS Events'!$D:$D,C14,'OOS Events'!$E:$E,">="&D14-90,'OOS Events'!$E:$E,"<"&D14) -> 0 | K14: =COUNTIF('OOS Events'!$B:$B,A14) -> 0 | L14: 1 | M14: 26 | N14: Standard / Medium
A15: B-4690 | B15: 110024421 | C15: 1088815 | D15: ApexNova Pharma | E15: SKRB | F15: 45590 | G15: 18 | H15: 45626 | I15: 45634 | J15: =COUNTIFS('OOS Events'!$C:$C,B15,'OOS Events'!$D:$D,C15,'OOS Events'!$E:$E,">="&D15-90,'OOS Events'!$E:$E,"<"&D15) -> 0 | K15: =COUNTIF('OOS Events'!$B:$B,A15) -> 0 | L15: 0 | M15: 22 | N15: Sterility / High
A16: B-4553 | B16: 110036099 | C16: 1077103 | D16: Evergreen BioWorks | E16: SCNC | F16: 45591 | G16: 18 | H16: 45616 | I16: 45621 | J16: =COUNTIFS('OOS Events'!$C:$C,B16,'OOS Events'!$D:$D,C16,'OOS Events'!$E:$E,">="&D16-90,'OOS Events'!$E:$E,"<"&D16) -> 0 | K16: =COUNTIF('OOS Events'!$B:$B,A16) -> 2 | L16: 0 | M16: 35 | N16: Extended / Medium
... A604: B-4670 | B604: 110037819 | C604: 1077103 | D604: Evergreen BioWorks | E604: SUSC | F604: 46308 | G604: 24 | H604: 46337 | I604: 46337 | J604: =COUNTIFS('OOS Events'!$C:$C,B604,'OOS Events'!$D:$D,C604,'OOS Events'!$E:$E,">="&D604-90,'OOS Events'!$E:$E,"<"&D604) -> 0 | K604: =COUNTIF('OOS Events'!$B:$B,A604) -> 0 | L604: 1 | M604: 19 | N604: Extended / Medium

Sheet OOS Events
A1: OOS Event ID | B1: Batch ID | C1: Material | D1: Supplier Number | E1: Supplier Name | F1: CMO Site | G1: OOS Event Date | H1: OOS Status | I1: Closure Date | J1: Test Category
A2: OOS-00001 | B2: B-5022 | C2: 110032050 | D2: 1077103 | E2: Evergreen BioWorks | F2: SDEB | G2: 45578 | H2: Closed | I2: 45613 | J2: Identity
A3: OOS-00002 | B3: B-4768 | C3: 110028927 | D3: 1077103 | E3: Evergreen BioWorks | F3: SKRB | G3: 45576 | H3: Closed | I3: 45617 | J3: Purity
A4: OOS-00003 | B4: B-4631 | C4: 100011307 | D4: 1088815 | E4: ApexNova Pharma | F4: SUSB | G4: 45599 | H4: Closed | I4: 45628 | J4: Dissolution
A5: OOS-00004 | B5: B-4631 | C5: 100011307 | D5: 1088815 | E5: ApexNova Pharma | F5: SUSB | G5: 45569 | H5: Closed | I5: 45609 | J5: Dissolution
A6: OOS-00005 | B6: B-4983 | C6: 110041752 | D6: 1077103 | E6: Evergreen BioWorks | F6: SCNC | G6: 45556 | H6: Closed | I6: 45601 | J6: Dissolution
A7: OOS-00006 | B7: B-4553 | C7: 110036099 | D7: 1077103 | E7: Evergreen BioWorks | F7: SCNC | G7: 45555 | H7: Closed | I7: 45598 | J7: Sterility
A8: OOS-00007 | B8: B-4553 | C8: 110036099 | D8: 1077103 | E8: Evergreen BioWorks | F8: SCNC | G8: 45549 | H8: Closed | I8: 45586 | J8: Sterility
A9: OOS-00008 | B9: B-5042 | C9: 110032046 | D9: 1077103 | E9: Evergreen BioWorks | F9: SUSC | G9: 45609 | H9: Closed | I9: 45626 | J9: Sterility
A10: OOS-00009 | B10: B-4905 | C10: 310173030 | D10: 1088815 | E10: ApexNova Pharma | F10: SUSB | G10: 45597 | H10: Closed | I10: 45642 | J10: Identity
A11: OOS-00010 | B11: B-5003 | C11: 110036560 | D11: 1077103 | E11: Evergreen BioWorks | F11: SUSB | G11: 45566 | H11: Closed | I11: 45599 | J11: Assay
A12: OOS-00011 | B12: B-4866 | C12: 310461150 | D12: 1077103 | E12: Evergreen BioWorks | F12: SKRB | G12: 45596 | H12: Closed | I12: 45616 | J12: Identity
A13: OOS-00012 | B13: B-4866 | C13: 310461150 | D13: 1077103 | E13: Evergreen BioWorks | F13: SKRB | G13: 45626 | H13: Closed | I13: 45650 | J13: Dissolution
... A201: OOS-00200 | B201: B-5078 | C201: 110029756 | D201: 1076355 | E201: BluePeak Life Sciences | F201: SKRB | G201: 46196 | H201: Closed | I201: 46235 | J201: Identity
A202: OOS-00201 | B202: B-4902 | C202: 110032050 | D202: 1077103 | E202: Evergreen BioWorks | F202: SDEB | G202: 46211 | H202: Open | J202: Identity
A203: OOS-00202 | B203: B-4648 | C203: 110028927 | D203: 1077103 | E203: Evergreen BioWorks | F203: SUSC | G203: 46236 | H203: Open | J203: Dissolution
A204: OOS-00203 | B204: B-4824 | C204: 110041756 | D204: 1077103 | E204: Evergreen BioWorks | F204: SUSC | G204: 46245 | H204: Closed | I204: 46258 | J204: Dissolution
A205: OOS-00204 | B205: B-4824 | C205: 110041756 | D205: 1077103 | E205: Evergreen BioWorks | F205: SUSC | G205: 46206 | H205: Open | J205: Purity
A206: OOS-00205 | B206: B-4785 | C206: 310173030 | D206: 1088815 | E206: ApexNova Pharma | F206: SUSB | G206: 46196 | H206: Closed | I206: 46234 | J206: Sterility
A207: OOS-00206 | B207: B-4785 | C207: 310173030 | D207: 1088815 | E207: ApexNova Pharma | F207: SUSB | G207: 46246 | H207: Open | J207: Identity
A208: OOS-00207 | B208: B-4746 | C208: 310461150 | D208: 1077103 | E208: Evergreen BioWorks | F208: SDEB | G208: 46255 | H208: Closed | I208: 46276 | J208: Assay
A209: OOS-00208 | B209: B-5020 | C209: 100011556 | D209: 1088815 | E209: ApexNova Pharma | F209: SKRB | G209: 46203 | H209: Closed | I209: 46242 | J209: Dissolution
A210: OOS-00209 | B210: B-4766 | C210: 110025083 | D210: 1088815 | E210: ApexNova Pharma | F210: SUSC | G210: 46205 | H210: Closed | I210: 46217 | J210: Sterility
A211: OOS-00210 | B211: B-4629 | C211: 110034865 | D211: 1086308 | E211: HelixBridge Laboratories | F211: SCNC | G211: 46202 | H211: Closed | I211: 46226 | J211: Identity
A212: OOS-00211 | B212: B-4942 | C212: 110032050 | D212: 1077103 | E212: Evergreen BioWorks | F212: SUSC | G212: 46246 | H212: Open | J212: Identity
A213: OOS-00212 | B213: B-4610 | C213: 110024421 | D213: 1088815 | E213: ApexNova Pharma | F213: SKRB | G213: 46282 | H213: Closed | I213: 46310 | J213: Dissolution
A214: OOS-00213 | B214: B-4786 | C214: 310461150 | D214: 1077103 | E214: Evergreen BioWorks | F214: SKRB | G214: 46269 | H214: Closed | I214: 46303 | J214: Identity
A215: OOS-00214 | B215: B-4747 | C215: 100012361 | D215: 1088815 | E215: ApexNova Pharma | F215: SCNC | G215: 46257 | H215: Open | J215: Sterility
A216: OOS-00215 | B216: B-5021 | C216: 110024083 | D216: 1086308 | E216: HelixBridge Laboratories | F216: SSEC | G216: 46283 | H216: Open | J216: Dissolution
A217: OOS-00216 | B217: B-5021 | C217: 110024083 | D217: 1086308 | E217: HelixBridge Laboratories | F217: SSEC | G217: 46250 | H217: Open | J217: Dissolution
A218: OOS-00217 | B218: B-5119 | C218: 110032049 | D218: 1077103 | E218: Evergreen BioWorks | F218: SSEC | G218: 46264 | H218: Closed | I218: 46299 | J218: Assay
A219: OOS-00218 | B219: B-4943 | C219: 110041752 | D219: 1077103 | E219: Evergreen BioWorks | F219: SUSB | G219: 46267 | H219: Closed | I219: 46278 | J219: Purity
A220: OOS-00219 | B220: B-4943 | C220: 110041752 | D220: 1077103 | E220: Evergreen BioWorks | F220: SUSB | G220: 46242 | H220: Closed | I220: 46277 | J220: Identity
A221: OOS-00220 | B221: B-4689 | C221: 110028926 | D221: 1077103 | E221: Evergreen BioWorks | F221: SUSB | G221: 46245 | H221: Closed | I221: 46252 | J221: Purity
A222: OOS-00221 | B222: B-5041 | C222: 110025554 | D222: 1083989 | E222: VertexHill Biotech | F222: SCNC | G222: 46279 | H222: Open | J222: Assay
A223: OOS-00222 | B223: B-4904 | C223: 110041756 | D223: 1077103 | E223: Evergreen BioWorks | F223: SUSC | G223: 46273 | H223: Open | J223: Identity
A224: OOS-00223 | B224: B-4865 | C224: 310173030 | D224: 1088815 | E224: ApexNova Pharma | F224: SUSB | G224: 46315 | H224: Open | J224: Identity
A225: OOS-00224 | B225: B-4924 | C225: 8005032 | D225: 1076381 | E225: HelixBridge Laboratories | F225: SKRB | G225: 46250 | H225: Open | J225: Identity
A226: OOS-00225 | B226: B-5100 | C226: 100011556 | D226: 1088815 | E226: ApexNova Pharma | F226: SKRB | G226: 46335 | H226: Closed | I226: 46367 | J226: Purity
A227: OOS-00226 | B227: B-4846 | C227: 110025083 | D227: 1088815 | E227: ApexNova Pharma | F227: SDEB | G227: 46259 | H227: Closed | I227: 46295 | J227: Purity
...

Sheet Data Dictionary
A1: Column / Sheet | D1: Definition | E1: Feature Timing / Leakage Rule | F1: Origin
A2: Historical Batch Data | D2: One row per historical batch | E2: All predictor features are evaluated at Prediction / Start Date | F2: Synthetic
A3: Batch ID | D3: Unique batch identifier | E3: Known at prediction | F3: Synthetic
A4: Material | B4: Supplier Number | C4: Supplier Name | D4: Material identifier repeated across batches | E4: Known at prediction | F4: Based on source materials; repeated synthetically
A5: CMO Site | B5: SYN-O Site | C5: NorthStar Biologics Ltd. | D5: Manufacturing/QC site; repeated by material | E5: Known at prediction | F5: Synthetic
A6: Prediction / Start Date | B6: SYN-t Date | C6: HelixBridge Laboratories | D6: Date batch enters QC and prediction is made | E6: Anchor date for point-in-time features | F6: Synthetic
A7: QC Backlog at Start | B7: SYN- Start | C7: SilverLine Therapeutics | D7: Open QC workload at site on prediction date | E7: Snapshot at prediction date only | F7: Synthetic
A8: Recent OOS Count - Prior 90 Days | B8: SYN-0 Days | C8: SummitCore Healthcare | D8: OOS events for same Material and Site from D-90 through D-1 | E8: Excludes events on/after prediction date | F8: Formula from OOS Events
A9: Number of OOS Events (Batch) | B9: SYN-Batch) | C9: BluePeak Life Sciences | D9: OOS event count attached to the current batch | E9: Outcome/diagnostic; do not use as a predictor if not known at prediction | F9: Formula from OOS Events
A10: OOS Events | B10: SYN-Events | C10: NovaCrest Manufacturing | D10: Event-level OOS table with event and closure dates | E10: Filter OOS Event Date strictly before prediction date for model features | F10: Synthetic
A11: Repeated history | B11: SYN-istory | C11: Pioneer Clinical Supplies | D11: Each material appears across multiple batches and mostly within a consistent primary site | E11: Supports material/site lag and aggregate features | F11: Synthetic design
A12: Supplier Number | B12: Supplier identifier matched by Material from the source workbook | C12: Known at prediction | D12: Matched from source data
A13: Supplier Name | B13: Dummy supplier name assigned consistently to the matched supplier number | C13: Known at prediction | D13: Synthetic
